Workbook

Sheet Summary
A1: Subscription Revenue Forecast - Summary
A2: Simulated business for portfolio use; not real company data. Change inputs on the Inputs tab.
B4: FY2026 | C4: FY2027 | D4: YoY growth
A5: Net revenue, constant currency ($) | B5: =SUM(Forecast!B18:M18) -> 4279471.4 | C5: =SUM(Forecast!N18:Y18) -> 5198414.8 | D5: =IFERROR(C5/B5-1,0) -> 0.21473293
A6: Net revenue, selected FX scenario ($) | B6: =SUM(Forecast!B19:M19) -> 4279471.4 | C6: =SUM(Forecast!N19:Y19) -> 5198414.8 | D6: =IFERROR(C6/B6-1,0) -> 0.21473293
A7: Ending active subscribers | B7: =Forecast!M16 -> 50942.078 | C7: =Forecast!Y16 -> 61290.737 | D7: =IFERROR(C7/B7-1,0) -> 0.20314559
A8: FX impact vs constant currency ($) | B8: =B6-B5 -> 0 | C8: =C6-C5 -> 0
A10: Check against Python model
A11: Python forecast, constant currency ($) | B11: 4279471.4 | C11: 5198414.8
A12: Difference (Excel vs Python) | B12: =IFERROR(B5/B11-1,0) -> 0 | C12: =IFERROR(C5/C11-1,0) -> 0
A14: Scenario in use | B14: =Inputs!$B$16 -> Base

Sheet Inputs
A1: Subscription Revenue Forecast - Driver Inputs
A2: Blue = input you can change. Yellow = key assumption. Black = formula. Green = link to another sheet.
A4: Trial starts, Jan 2026 (trend, before seasonality) | B4: 8181.64
A5: Trial starts growth, month over month | B5: 0.012599768
A6: December seasonality factor | B6: 1.094318
A7: Trial starts in Dec 2025 (convert in Jan 2026) | B7: 9584
A8: Trial-to-paid conversion | B8: 0.36704657
A9: Share of new payers choosing annual plan | B9: 0.25243682
A10: Churn curve a (churn = a x tenure^b) | B10: 0.17394266
A11: Churn curve b | B11: -0.456505
A12: Annual-plan renewal rate | B12: 0.70091403
A13: Net ARPU, monthly plan (USD / month, after fees) | B13: 8.4333016
A14: Net ARPU, annual plan (USD / month recognized) | B14: 6.6552513
A15: Non-USD share of revenue | B15: 0.47042016
A16: FX scenario (pick from list) | B16: Base
A18: FX scenario table
A19: Scenario | B19: Non-USD currencies vs USD
A20: Base | B20: 0
A21: USD +10% | B21: -0.1
A22: USD -10% | B22: 0.1
A23: Selected FX shock | B23: =INDEX($B$20:$B$22,MATCH($B$16,$A$20:$A$22,0)) -> 0

Sheet Churn Curve
A1: Monthly-Plan Churn Curve and Survival
A3: Paid tenure (months) | B3: Churn rate | C3: Survival (still active)
A4: 0 | B4: 0 | C4: 1
A5: 1 | B5: =MIN(1,Inputs!$B$10*A5^Inputs!$B$11) -> 0.17394266 | C5: =C4*(1-B5) -> 0.82605734
A6: 2 | B6: =MIN(1,Inputs!$B$10*A6^Inputs!$B$11) -> 0.12676064 | C6: =C5*(1-B6) -> 0.72134578
A7: 3 | B7: =MIN(1,Inputs!$B$10*A7^Inputs!$B$11) -> 0.10534111 | C7: =C6*(1-B7) -> 0.64535842
A8: 4 | B8: =MIN(1,Inputs!$B$10*A8^Inputs!$B$11) -> 0.092376758 | C8: =C7*(1-B8) -> 0.5857423
A9: 5 | B9: =MIN(1,Inputs!$B$10*A9^Inputs!$B$11) -> 0.083430109 | C9: =C8*(1-B9) -> 0.53687376
A10: 6 | B10: =MIN(1,Inputs!$B$10*A10^Inputs!$B$11) -> 0.076767284 | C10: =C9*(1-B10) -> 0.49565942
A11: 7 | B11: =MIN(1,Inputs!$B$10*A11^Inputs!$B$11) -> 0.071550822 | C11: =C10*(1-B11) -> 0.46019458
A12: 8 | B12: =MIN(1,Inputs!$B$10*A12^Inputs!$B$11) -> 0.067319521 | C12: =C11*(1-B12) -> 0.4292145
A13: 9 | B13: =MIN(1,Inputs!$B$10*A13^Inputs!$B$11) -> 0.06379544 | C13: =C12*(1-B13) -> 0.40183257
A14: 10 | B14: =MIN(1,Inputs!$B$10*A14^Inputs!$B$11) -> 0.060799654 | C14: =C13*(1-B14) -> 0.37740129
A15: 11 | B15: =MIN(1,Inputs!$B$10*A15^Inputs!$B$11) -> 0.058211011 | C15: =C14*(1-B15) -> 0.35543238
A16: 12 | B16: =MIN(1,Inputs!$B$10*A16^Inputs!$B$11) -> 0.055944124 | C16: =C15*(1-B16) -> 0.33554803
... A28: 24 | B28: =MIN(1,Inputs!$B$10*A28^Inputs!$B$11) -> 0.040769255 | C28: =C27*(1-B28) -> 0.18954948

Sheet Forecast
A1: Cohort-Based Revenue Forecast, Jan 2026 - Dec 2027 (USD)
A3: Month | B3: 2026-01 | C3: 2026-02 | D3: 2026-03 | E3: 2026-04 | F3: 2026-05 | G3: 2026-06 | H3: 2026-07 | I3: 2026-08 | J3: 2026-09 | K3: 2026-10 | L3: 2026-11 | M3: 2026-12 | N3: 2027-01 | O3: 2027-02 | P3: 2027-03 | Q3: 2027-04 | R3: 2027-05 | S3: 2027-06 | T3: 2027-07 | U3: 2027-08 | V3: 2027-09 | W3: 2027-10 | X3: 2027-11 | Y3: 2027-12
A4: Forecast month # | B4: 1 | C4: 2 | D4: 3 | E4: 4 | F4: 5 | G4: 6 | H4: 7 | I4: 8 | J4: 9 | K4: 10 | L4: 11 | M4: 12 | N4: 13 | O4: 14 | P4: 15 | Q4: 16 | R4: 17 | S4: 18 | T4: 19 | U4: 20 | V4: 21 | W4: 22 | X4: 23 | Y4: 24
A5: Trial starts | B5: =Inputs!$B$4*(1+Inputs!$B$5)^(B$4-1)*IF(MOD(B$4,12)=0,Inputs!$B$6,1) -> 8181.64 | C5: =Inputs!$B$4*(1+Inputs!$B$5)^(C$4-1)*IF(MOD(C$4,12)=0,Inputs!$B$6,1) -> 8284.7267 | D5: =Inputs!$B$4*(1+Inputs!$B$5)^(D$4-1)*IF(MOD(D$4,12)=0,Inputs!$B$6,1) -> 8389.1124 | E5: =Inputs!$B$4*(1+Inputs!$B$5)^(E$4-1)*IF(MOD(E$4,12)=0,Inputs!$B$6,1) -> 8494.8132 | F5: =Inputs!$B$4*(1+Inputs!$B$5)^(F$4-1)*IF(MOD(F$4,12)=0,Inputs!$B$6,1) -> 8601.8459 | G5: =Inputs!$B$4*(1+Inputs!$B$5)^(G$4-1)*IF(MOD(G$4,12)=0,Inputs!$B$6,1) -> 8710.2272 | H5: =Inputs!$B$4*(1+Inputs!$B$5)^(H$4-1)*IF(MOD(H$4,12)=0,Inputs!$B$6,1) -> 8819.974 | I5: =Inputs!$B$4*(1+Inputs!$B$5)^(I$4-1)*IF(MOD(I$4,12)=0,Inputs!$B$6,1) -> 8931.1036 | ... Y5: =Inputs!$B$4*(1+Inputs!$B$5)^(Y$4-1)*IF(MOD(Y$4,12)=0,Inputs!$B$6,1) -> 11941.362
A6: New paying subscribers | B6: =Inputs!$B$7*Inputs!$B$8 -> 3517.7744 | C6: =B5*Inputs!$B$8 -> 3003.0429 | D6: =C5*Inputs!$B$8 -> 3040.8806 | E6: =D5*Inputs!$B$8 -> 3079.195 | F6: =E5*Inputs!$B$8 -> 3117.9921 | G6: =F5*Inputs!$B$8 -> 3157.2781 | H6: =G5*Inputs!$B$8 -> 3197.059 | I6: =H5*Inputs!$B$8 -> 3237.3413 | J6: =I5*Inputs!$B$8 -> 3278.131 | ... Y6: =X5*Inputs!$B$8 -> 3955.4296
A7: of which monthly plan | B7: =B6*(1-Inputs!$B$9) -> 2629.7586 | C7: =C6*(1-Inputs!$B$9) -> 2244.9643 | D7: =D6*(1-Inputs!$B$9) -> 2273.2504 | E7: =E6*(1-Inputs!$B$9) -> 2301.8928 | F7: =F6*(1-Inputs!$B$9) -> 2330.8961 | G7: =G6*(1-Inputs!$B$9) -> 2360.2648 | H7: =H6*(1-Inputs!$B$9) -> 2390.0036 | I7: =I6*(1-Inputs!$B$9) -> 2420.1171 | ... Y7: =Y6*(1-Inputs!$B$9) -> 2956.9335
A8: of which annual plan | B8: =B6*Inputs!$B$9 -> 888.01577 | C8: =C6*Inputs!$B$9 -> 758.0786 | D8: =D6*Inputs!$B$9 -> 767.63021 | E8: =E6*Inputs!$B$9 -> 777.30218 | F8: =F6*Inputs!$B$9 -> 787.096 | G8: =G6*Inputs!$B$9 -> 797.01323 | H8: =H6*Inputs!$B$9 -> 807.05541 | I8: =I6*Inputs!$B$9 -> 817.22412 | ... Y8: =Y6*Inputs!$B$9 -> 998.49606
A9: Subscribers
A10: Existing monthly subs (Dec 2025 base) | B10: 21514.673 | C10: 20105.406 | D10: 18902.001 | E10: 17844.554 | F10: 16899.527 | G10: 16045.211 | H10: 15266.332 | I10: 14551.541 | J10: 13892.075 | K10: 13280.968 | L10: 12712.559 | M10: 12182.165 | N10: 11685.851 | O10: 11220.275 | P10: 10782.567 | Q10: 10370.237 | R10: 9981.1134 | S10: 9613.2852 | T10: 9265.0619 | U10: 8934.94 | V10: 8621.5757 | W10: 8323.7625 | X10: 8040.4131 | Y10: 7770.5438
A11: New monthly-plan cohorts still active | B11: ='Cohort Waterfall'!B30 -> 2629.7586 | C11: ='Cohort Waterfall'!C30 -> 4417.2957 | D11: ='Cohort Waterfall'!D30 -> 6024.6849 | E11: ='Cohort Waterfall'!E30 -> 7496.2603 | F11: ='Cohort Waterfall'!F30 -> 8861.3586 | G11: ='Cohort Waterfall'!G30 -> 10140.06 | H11: ='Cohort Waterfall'!H30 -> 11346.912 | I11: ='Cohort Waterfall'!I30 -> 12492.93 | ... Y11: ='Cohort Waterfall'!Y30 -> 26723.737
A12: Active monthly-plan subs | B12: =B10+B11 -> 24144.431 | C12: =C10+C11 -> 24522.702 | D12: =D10+D11 -> 24926.686 | E12: =E10+E11 -> 25340.815 | F12: =F10+F11 -> 25760.886 | G12: =G10+G11 -> 26185.271 | H12: =H10+H11 -> 26613.244 | I12: =I10+I11 -> 27044.472 | ... Y12: =Y10+Y11 -> 34494.281
A13: Existing annual subs (Dec 2025 base) | B13: 17236.056 | C13: 16830.794 | D13: 16410.579 | E13: 16006.214 | F13: 15581.213 | G13: 15144.249 | H13: 14695.919 | I13: 14201.53 | J13: 13752.003 | K13: 13300.384 | L13: 12835.903 | M13: 12369.03 | N13: 12080.993 | O13: 11796.94 | P13: 11502.405 | Q13: 11218.98 | R13: 10921.091 | S13: 10614.816 | T13: 10300.576 | U13: 9954.0515 | V13: 9638.9722 | W13: 9322.4256 | X13: 8996.8647 | Y13: 8669.6267
A14: New annual-plan cohorts still active | B14: ='Cohort Waterfall'!B59 -> 888.01577 | C14: ='Cohort Waterfall'!C59 -> 1646.0944 | D14: ='Cohort Waterfall'!D59 -> 2413.7246 | E14: ='Cohort Waterfall'!E59 -> 3191.0268 | F14: ='Cohort Waterfall'!F59 -> 3978.1228 | G14: ='Cohort Waterfall'!G59 -> 4775.136 | H14: ='Cohort Waterfall'!H59 -> 5582.1914 | I14: ='Cohort Waterfall'!I59 -> 6399.4155 | ... Y14: ='Cohort Waterfall'!Y59 -> 18126.829
A15: Active annual-plan subs | B15: =B13+B14 -> 18124.072 | C15: =C13+C14 -> 18476.889 | D15: =D13+D14 -> 18824.303 | E15: =E13+E14 -> 19197.241 | F15: =F13+F14 -> 19559.336 | G15: =G13+G14 -> 19919.385 | H15: =H13+H14 -> 20278.11 | I15: =I13+I14 -> 20600.945 | ... Y15: =Y13+Y14 -> 26796.456
A16: Total active subscribers | B16: =B12+B15 -> 42268.503 | C16: =C12+C15 -> 42999.591 | D16: =D12+D15 -> 43750.989 | E16: =E12+E15 -> 44538.056 | F16: =F12+F15 -> 45320.222 | G16: =G12+G15 -> 46104.655 | H16: =H12+H15 -> 46891.354 | I16: =I12+I15 -> 47645.417 | ... Y16: =Y12+Y15 -> 61290.737
A17: Revenue
A18: Net revenue, constant currency ($) | B18: =B12*Inputs!$B$13+B15*Inputs!$B$14 -> 324237.52 | C18: =C12*Inputs!$B$13+C15*Inputs!$B$14 -> 329775.68 | D18: =D12*Inputs!$B$13+D15*Inputs!$B$14 -> 335494.73 | E18: =E12*Inputs!$B$13+E15*Inputs!$B$14 -> 341469.2 | F18: =F12*Inputs!$B$13+F15*Inputs!$B$14 -> 347421.62 | G18: =G12*Inputs!$B$13+G15*Inputs!$B$14 -> 353396.8 | H18: =H12*Inputs!$B$13+H15*Inputs!$B$14 -> 359393.43 | I18: =I12*Inputs!$B$13+I15*Inputs!$B$14 -> 365178.66 | ... Y18: =Y12*Inputs!$B$13+Y15*Inputs!$B$14 -> 469237.82
A19: Net revenue, selected FX scenario ($) | B19: =B18*(1+Inputs!$B$23*Inputs!$B$15) -> 324237.52 | C19: =C18*(1+Inputs!$B$23*Inputs!$B$15) -> 329775.68 | D19: =D18*(1+Inputs!$B$23*Inputs!$B$15) -> 335494.73 | E19: =E18*(1+Inputs!$B$23*Inputs!$B$15) -> 341469.2 | F19: =F18*(1+Inputs!$B$23*Inputs!$B$15) -> 347421.62 | G19: =G18*(1+Inputs!$B$23*Inputs!$B$15) -> 353396.8 | H19: =H18*(1+Inputs!$B$23*Inputs!$B$15) -> 359393.43 | I19: =I18*(1+Inputs!$B$23*Inputs!$B$15) -> 365178.66 | ... Y19: =Y18*(1+Inputs!$B$23*Inputs!$B$15) -> 469237.82

Sheet Cohort Waterfall
A1: Cohort Waterfall: active subscribers by start month (rows) and calendar month (columns)
A4: Monthly plan: new payers x survival from the churn curve
A5: Cohort start | B5: 2026-01 | C5: 2026-02 | D5: 2026-03 | E5: 2026-04 | F5: 2026-05 | G5: 2026-06 | H5: 2026-07 | I5: 2026-08 | J5: 2026-09 | K5: 2026-10 | L5: 2026-11 | M5: 2026-12 | N5: 2027-01 | O5: 2027-02 | P5: 2027-03 | Q5: 2027-04 | R5: 2027-05 | S5: 2027-06 | T5: 2027-07 | U5: 2027-08 | V5: 2027-09 | W5: 2027-10 | X5: 2027-11 | Y5: 2027-12
A6: 2026-01 | B6: =Forecast!B$7*INDEX('Churn Curve'!$C$4:$C$28,0+1) -> 2629.7586 | C6: =Forecast!B$7*INDEX('Churn Curve'!$C$4:$C$28,1+1) -> 2172.3314 | D6: =Forecast!B$7*INDEX('Churn Curve'!$C$4:$C$28,2+1) -> 1896.9653 | E6: =Forecast!B$7*INDEX('Churn Curve'!$C$4:$C$28,3+1) -> 1697.1369 | F6: =Forecast!B$7*INDEX('Churn Curve'!$C$4:$C$28,4+1) -> 1540.3609 | G6: =Forecast!B$7*INDEX('Churn Curve'!$C$4:$C$28,5+1) -> 1411.8484 | H6: =Forecast!B$7*INDEX('Churn Curve'!$C$4:$C$28,6+1) -> 1303.4646 | I6: =Forecast!B$7*INDEX('Churn Curve'!$C$4:$C$28,7+1) -> 1210.2007 | J6: =Forecast!B$7*INDEX('Churn Curve'!$C$4:$C$28,8+1) -> 1128.7305 | K6: =Forecast!B$7*INDEX('Churn Curve'!$C$4:$C$28,9+1) -> 1056.7227 | L6: =Forecast!B$7*INDEX('Churn Curve'!$C$4:$C$28,10+1) -> 992.47429 | M6: =Forecast!B$7*INDEX('Churn Curve'!$C$4:$C$28,11+1) -> 934.70136 | N6: =Forecast!B$7*INDEX('Churn Curve'!$C$4:$C$28,12+1) -> 882.41031 | O6: =Forecast!B$7*INDEX('Churn Curve'!$C$4:$C$28,13+1) -> 834.8159 | P6: =Forecast!B$7*INDEX('Churn Curve'!$C$4:$C$28,14+1) -> 791.2864 | Q6: =Forecast!B$7*INDEX('Churn Curve'!$C$4:$C$28,15+1) -> 751.3059 | R6: =Forecast!B$7*INDEX('Churn Curve'!$C$4:$C$28,16+1) -> 714.44753 | S6: =Forecast!B$7*INDEX('Churn Curve'!$C$4:$C$28,17+1) -> 680.35412 | T6: =Forecast!B$7*INDEX('Churn Curve'!$C$4:$C$28,18+1) -> 648.72385 | U6: =Forecast!B$7*INDEX('Churn Curve'!$C$4:$C$28,19+1) -> 619.29939 | V6: =Forecast!B$7*INDEX('Churn Curve'!$C$4:$C$28,20+1) -> 591.85964 | W6: =Forecast!B$7*INDEX('Churn Curve'!$C$4:$C$28,21+1) -> 566.21332 | X6: =Forecast!B$7*INDEX('Churn Curve'!$C$4:$C$28,22+1) -> 542.19384 | Y6: =Forecast!B$7*INDEX('Churn Curve'!$C$4:$C$28,23+1) -> 519.65534
A7: 2026-02 | B7: 0 | C7: =Forecast!C$7*INDEX('Churn Curve'!$C$4:$C$28,0+1) -> 2244.9643 | D7: =Forecast!C$7*INDEX('Churn Curve'!$C$4:$C$28,1+1) -> 1854.4693 | E7: =Forecast!C$7*INDEX('Churn Curve'!$C$4:$C$28,2+1) -> 1619.3955 | F7: =Forecast!C$7*INDEX('Churn Curve'!$C$4:$C$28,3+1) -> 1448.8066 | G7: =Forecast!C$7*INDEX('Churn Curve'!$C$4:$C$28,4+1) -> 1314.9706 | H7: =Forecast!C$7*INDEX('Churn Curve'!$C$4:$C$28,5+1) -> 1205.2624 | I7: =Forecast!C$7*INDEX('Churn Curve'!$C$4:$C$28,6+1) -> 1112.7377 | J7: =Forecast!C$7*INDEX('Churn Curve'!$C$4:$C$28,7+1) -> 1033.1204 | K7: =Forecast!C$7*INDEX('Churn Curve'!$C$4:$C$28,8+1) -> 963.57124 | L7: =Forecast!C$7*INDEX('Churn Curve'!$C$4:$C$28,9+1) -> 902.09979 | M7: =Forecast!C$7*INDEX('Churn Curve'!$C$4:$C$28,10+1) -> 847.25244 | N7: =Forecast!C$7*INDEX('Churn Curve'!$C$4:$C$28,11+1) -> 797.93301 | O7: =Forecast!C$7*INDEX('Churn Curve'!$C$4:$C$28,12+1) -> 753.29335 | P7: =Forecast!C$7*INDEX('Churn Curve'!$C$4:$C$28,13+1) -> 712.6631 | Q7: =Forecast!C$7*INDEX('Churn Curve'!$C$4:$C$28,14+1) -> 675.50297 | R7: =Forecast!C$7*INDEX('Churn Curve'!$C$4:$C$28,15+1) -> 641.37253 | S7: =Forecast!C$7*INDEX('Churn Curve'!$C$4:$C$28,16+1) -> 609.90739 | T7: =Forecast!C$7*INDEX('Churn Curve'!$C$4:$C$28,17+1) -> 580.80264 | U7: =Forecast!C$7*INDEX('Churn Curve'!$C$4:$C$28,18+1) -> 553.8006 | V7: =Forecast!C$7*INDEX('Churn Curve'!$C$4:$C$28,19+1) -> 528.68162 | W7: =Forecast!C$7*INDEX('Churn Curve'!$C$4:$C$28,20+1) -> 505.25694 | X7: =Forecast!C$7*INDEX('Churn Curve'!$C$4:$C$28,21+1) -> 483.36326 | Y7: =Forecast!C$7*INDEX('Churn Curve'!$C$4:$C$28,22+1) -> 462.85839
A8: 2026-03 | B8: 0 | C8: 0 | D8: =Forecast!D$7*INDEX('Churn Curve'!$C$4:$C$28,0+1) -> 2273.2504 | E8: =Forecast!D$7*INDEX('Churn Curve'!$C$4:$C$28,1+1) -> 1877.8351 | F8: =Forecast!D$7*INDEX('Churn Curve'!$C$4:$C$28,2+1) -> 1639.7996 | G8: =Forecast!D$7*INDEX('Churn Curve'!$C$4:$C$28,3+1) -> 1467.0613 | H8: =Forecast!D$7*INDEX('Churn Curve'!$C$4:$C$28,4+1) -> 1331.5389 | I8: =Forecast!D$7*INDEX('Churn Curve'!$C$4:$C$28,5+1) -> 1220.4485 | J8: =Forecast!D$7*INDEX('Churn Curve'!$C$4:$C$28,6+1) -> 1126.7579 | K8: =Forecast!D$7*INDEX('Churn Curve'!$C$4:$C$28,7+1) -> 1046.1375 | L8: =Forecast!D$7*INDEX('Churn Curve'!$C$4:$C$28,8+1) -> 975.71202 | M8: =Forecast!D$7*INDEX('Churn Curve'!$C$4:$C$28,9+1) -> 913.46604 | N8: =Forecast!D$7*INDEX('Churn Curve'!$C$4:$C$28,10+1) -> 857.92762 | O8: =Forecast!D$7*INDEX('Churn Curve'!$C$4:$C$28,11+1) -> 807.98679 | P8: =Forecast!D$7*INDEX('Churn Curve'!$C$4:$C$28,12+1) -> 762.78467 | Q8: =Forecast!D$7*INDEX('Churn Curve'!$C$4:$C$28,13+1) -> 721.64249 | R8: =Forecast!D$7*INDEX('Churn Curve'!$C$4:$C$28,14+1) -> 684.01415 | S8: =Forecast!D$7*INDEX('Churn Curve'!$C$4:$C$28,15+1) -> 649.45368 | T8: =Forecast!D$7*INDEX('Churn Curve'!$C$4:$C$28,16+1) -> 617.59208 | U8: =Forecast!D$7*INDEX('Churn Curve'!$C$4:$C$28,17+1) -> 588.12062 | V8: =Forecast!D$7*INDEX('Churn Curve'!$C$4:$C$28,18+1) -> 560.77836 | W8: =Forecast!D$7*INDEX('Churn Curve'!$C$4:$C$28,19+1) -> 535.34288 | X8: =Forecast!D$7*INDEX('Churn Curve'!$C$4:$C$28,20+1) -> 511.62306 | Y8: =Forecast!D$7*INDEX('Churn Curve'!$C$4:$C$28,21+1) -> 489.45353
A9: 2026-04 | B9: 0 | C9: 0 | D9: 0 | E9: =Forecast!E$7*INDEX('Churn Curve'!$C$4:$C$28,0+1) -> 2301.8928 | F9: =Forecast!E$7*INDEX('Churn Curve'!$C$4:$C$28,1+1) -> 1901.4954 | G9: =Forecast!E$7*INDEX('Churn Curve'!$C$4:$C$28,2+1) -> 1660.4607 | H9: =Forecast!E$7*INDEX('Churn Curve'!$C$4:$C$28,3+1) -> 1485.5459 | I9: =Forecast!E$7*INDEX('Churn Curve'!$C$4:$C$28,4+1) -> 1348.316 | J9: =Forecast!E$7*INDEX('Churn Curve'!$C$4:$C$28,5+1) -> 1235.8258 | K9: =Forecast!E$7*INDEX('Churn Curve'!$C$4:$C$28,6+1) -> 1140.9548 | L9: =Forecast!E$7*INDEX('Churn Curve'!$C$4:$C$28,7+1) -> 1059.3186 | M9: =Forecast!E$7*INDEX('Churn Curve'!$C$4:$C$28,8+1) -> 988.00576 | N9: =Forecast!E$7*INDEX('Churn Curve'!$C$4:$C$28,9+1) -> 924.9755 | O9: =Forecast!E$7*INDEX('Churn Curve'!$C$4:$C$28,10+1) -> 868.73731 | P9: =Forecast!E$7*INDEX('Churn Curve'!$C$4:$C$28,11+1) -> 818.16723 | Q9: =Forecast!E$7*INDEX('Churn Curve'!$C$4:$C$28,12+1) -> 772.39558 | R9: =Forecast!E$7*INDEX('Churn Curve'!$C$4:$C$28,13+1) -> 730.73501 | S9: =Forecast!E$7*INDEX('Churn Curve'!$C$4:$C$28,14+1) -> 692.63257 | T9: =Forecast!E$7*INDEX('Churn Curve'!$C$4:$C$28,15+1) -> 657.63664 | U9: =Forecast!E$7*INDEX('Churn Curve'!$C$4:$C$28,16+1) -> 625.3736 | V9: =Forecast!E$7*INDEX('Churn Curve'!$C$4:$C$28,17+1) -> 595.5308 | W9: =Forecast!E$7*INDEX('Churn Curve'!$C$4:$C$28,18+1) -> 567.84404 | X9: =Forecast!E$7*INDEX('Churn Curve'!$C$4:$C$28,19+1) -> 542.08808 | Y9: =Forecast!E$7*INDEX('Churn Curve'!$C$4:$C$28,20+1) -> 518.06939
A10: 2026-05 | B10: 0 | C10: 0 | D10: 0 | E10: 0 | F10: =Forecast!F$7*INDEX('Churn Curve'!$C$4:$C$28,0+1) -> 2330.8961 | G10: =Forecast!F$7*INDEX('Churn Curve'!$C$4:$C$28,1+1) -> 1925.4538 | H10: =Forecast!F$7*INDEX('Churn Curve'!$C$4:$C$28,2+1) -> 1681.3821 | I10: =Forecast!F$7*INDEX('Churn Curve'!$C$4:$C$28,3+1) -> 1504.2634 | J10: =Forecast!F$7*INDEX('Churn Curve'!$C$4:$C$28,4+1) -> 1365.3044 | K10: =Forecast!F$7*INDEX('Churn Curve'!$C$4:$C$28,5+1) -> 1251.3969 | L10: =Forecast!F$7*INDEX('Churn Curve'!$C$4:$C$28,6+1) -> 1155.3306 | M10: =Forecast!F$7*INDEX('Churn Curve'!$C$4:$C$28,7+1) -> 1072.6657 | N10: =Forecast!F$7*INDEX('Churn Curve'!$C$4:$C$28,8+1) -> 1000.4544 | O10: =Forecast!F$7*INDEX('Churn Curve'!$C$4:$C$28,9+1) -> 936.62998 | P10: =Forecast!F$7*INDEX('Churn Curve'!$C$4:$C$28,10+1) -> 879.6832 | Q10: =Forecast!F$7*INDEX('Churn Curve'!$C$4:$C$28,11+1) -> 828.47595 | R10: =Forecast!F$7*INDEX('Churn Curve'!$C$4:$C$28,12+1) -> 782.12759 | S10: =Forecast!F$7*INDEX('Churn Curve'!$C$4:$C$28,13+1) -> 739.94211 | T10: =Forecast!F$7*INDEX('Churn Curve'!$C$4:$C$28,14+1) -> 701.35958 | U10: =Forecast!F$7*INDEX('Churn Curve'!$C$4:$C$28,15+1) -> 665.92271 | V10: =Forecast!F$7*INDEX('Churn Curve'!$C$4:$C$28,16+1) -> 633.25316 | W10: =Forecast!F$7*INDEX('Churn Curve'!$C$4:$C$28,17+1) -> 603.03435 | X10: =Forecast!F$7*INDEX('Churn Curve'!$C$4:$C$28,18+1) -> 574.99874 | Y10: =Forecast!F$7*INDEX('Churn Curve'!$C$4:$C$28,19+1) -> 548.91826
A11: 2026-06 | B11: 0 | C11: 0 | D11: 0 | E11: 0 | F11: 0 | G11: =Forecast!G$7*INDEX('Churn Curve'!$C$4:$C$28,0+1) -> 2360.2648 | H11: =Forecast!G$7*INDEX('Churn Curve'!$C$4:$C$28,1+1) -> 1949.7141 | I11: =Forecast!G$7*INDEX('Churn Curve'!$C$4:$C$28,2+1) -> 1702.5671 | J11: =Forecast!G$7*INDEX('Churn Curve'!$C$4:$C$28,3+1) -> 1523.2168 | K11: =Forecast!G$7*INDEX('Churn Curve'!$C$4:$C$28,4+1) -> 1382.507 | L11: =Forecast!G$7*INDEX('Churn Curve'!$C$4:$C$28,5+1) -> 1267.1643 | M11: =Forecast!G$7*INDEX('Churn Curve'!$C$4:$C$28,6+1) -> 1169.8875 | N11: =Forecast!G$7*INDEX('Churn Curve'!$C$4:$C$28,7+1) -> 1086.1811 | O11: =Forecast!G$7*INDEX('Churn Curve'!$C$4:$C$28,8+1) -> 1013.0599 | P11: =Forecast!G$7*INDEX('Churn Curve'!$C$4:$C$28,9+1) -> 948.4313 | Q11: =Forecast!G$7*INDEX('Churn Curve'!$C$4:$C$28,10+1) -> 890.767 | R11: =Forecast!G$7*INDEX('Churn Curve'!$C$4:$C$28,11+1) -> 838.91455 | S11: =Forecast!G$7*INDEX('Churn Curve'!$C$4:$C$28,12+1) -> 791.98221 | T11: =Forecast!G$7*INDEX('Churn Curve'!$C$4:$C$28,13+1) -> 749.26521 | U11: =Forecast!G$7*INDEX('Churn Curve'!$C$4:$C$28,14+1) -> 710.19655 | V11: =Forecast!G$7*INDEX('Churn Curve'!$C$4:$C$28,15+1) -> 674.31319 | W11: =Forecast!G$7*INDEX('Churn Curve'!$C$4:$C$28,16+1) -> 641.23201 | X11: =Forecast!G$7*INDEX('Churn Curve'!$C$4:$C$28,17+1) -> 610.63244 | Y11: =Forecast!G$7*INDEX('Churn Curve'!$C$4:$C$28,18+1) -> 582.24359
A12: 2026-07 | B12: 0 | C12: 0 | D12: 0 | E12: 0 | F12: 0 | G12: 0 | H12: =Forecast!H$7*INDEX('Churn Curve'!$C$4:$C$28,0+1) -> 2390.0036 | I12: =Forecast!H$7*INDEX('Churn Curve'!$C$4:$C$28,1+1) -> 1974.28 | J12: =Forecast!H$7*INDEX('Churn Curve'!$C$4:$C$28,2+1) -> 1724.019 | K12: =Forecast!H$7*INDEX('Churn Curve'!$C$4:$C$28,3+1) -> 1542.409 | L12: =Forecast!H$7*INDEX('Churn Curve'!$C$4:$C$28,4+1) -> 1399.9262 | M12: =Forecast!H$7*INDEX('Churn Curve'!$C$4:$C$28,5+1) -> 1283.1302 | N12: =Forecast!H$7*INDEX('Churn Curve'!$C$4:$C$28,6+1) -> 1184.6278 | O12: =Forecast!H$7*INDEX('Churn Curve'!$C$4:$C$28,7+1) -> 1099.8667 | P12: =Forecast!H$7*INDEX('Churn Curve'!$C$4:$C$28,8+1) -> 1025.8242 | Q12: =Forecast!H$7*INDEX('Churn Curve'!$C$4:$C$28,9+1) -> 960.38131 | R12: =Forecast!H$7*INDEX('Churn Curve'!$C$4:$C$28,10+1) -> 901.99046 | S12: =Forecast!H$7*INDEX('Churn Curve'!$C$4:$C$28,11+1) -> 849.48468 | T12: =Forecast!H$7*INDEX('Churn Curve'!$C$4:$C$28,12+1) -> 801.96101 | U12: =Forecast!H$7*INDEX('Churn Curve'!$C$4:$C$28,13+1) -> 758.70577 | V12: =Forecast!H$7*INDEX('Churn Curve'!$C$4:$C$28,14+1) -> 719.14486 | W12: =Forecast!H$7*INDEX('Churn Curve'!$C$4:$C$28,15+1) -> 682.80938 | X12: =Forecast!H$7*INDEX('Churn Curve'!$C$4:$C$28,16+1) -> 649.31138 | Y12: =Forecast!H$7*INDEX('Churn Curve'!$C$4:$C$28,17+1) -> 618.32627
A13: 2026-08 | B13: 0 | C13: 0 | D13: 0 | E13: 0 | F13: 0 | G13: 0 | H13: 0 | I13: =Forecast!I$7*INDEX('Churn Curve'!$C$4:$C$28,0+1) -> 2420.1171 | J13: =Forecast!I$7*INDEX('Churn Curve'!$C$4:$C$28,1+1) -> 1999.1555 | K13: =Forecast!I$7*INDEX('Churn Curve'!$C$4:$C$28,2+1) -> 1745.7413 | L13: =Forecast!I$7*INDEX('Churn Curve'!$C$4:$C$28,3+1) -> 1561.843 | M13: =Forecast!I$7*INDEX('Churn Curve'!$C$4:$C$28,4+1) -> 1417.565 | N13: =Forecast!I$7*INDEX('Churn Curve'!$C$4:$C$28,5+1) -> 1299.2974 | O13: =Forecast!I$7*INDEX('Churn Curve'!$C$4:$C$28,6+1) -> 1199.5538 | P13: =Forecast!I$7*INDEX('Churn Curve'!$C$4:$C$28,7+1) -> 1113.7248 | Q13: =Forecast!I$7*INDEX('Churn Curve'!$C$4:$C$28,8+1) -> 1038.7494 | R13: =Forecast!I$7*INDEX('Churn Curve'!$C$4:$C$28,9+1) -> 972.48189 | S13: =Forecast!I$7*INDEX('Churn Curve'!$C$4:$C$28,10+1) -> 913.35533 | T13: =Forecast!I$7*INDEX('Churn Curve'!$C$4:$C$28,11+1) -> 860.18799 | U13: =Forecast!I$7*INDEX('Churn Curve'!$C$4:$C$28,12+1) -> 812.06553 | V13: =Forecast!I$7*INDEX('Churn Curve'!$C$4:$C$28,13+1) -> 768.26529 | W13: =Forecast!I$7*INDEX('Churn Curve'!$C$4:$C$28,14+1) -> 728.20592 | X13: =Forecast!I$7*INDEX('Churn Curve'!$C$4:$C$28,15+1) -> 691.41262 | Y13: =Forecast!I$7*INDEX('Churn Curve'!$C$4:$C$28,16+1) -> 657.49255
A14: 2026-09 | B14: 0 | C14: 0 | D14: 0 | E14: 0 | F14: 0 | G14: 0 | H14: 0 | I14: 0 | J14: =Forecast!J$7*INDEX('Churn Curve'!$C$4:$C$28,0+1) -> 2450.61 | K14: =Forecast!J$7*INDEX('Churn Curve'!$C$4:$C$28,1+1) -> 2024.3444 | L14: =Forecast!J$7*INDEX('Churn Curve'!$C$4:$C$28,2+1) -> 1767.7372 | M14: =Forecast!J$7*INDEX('Churn Curve'!$C$4:$C$28,3+1) -> 1581.5218 | N14: =Forecast!J$7*INDEX('Churn Curve'!$C$4:$C$28,4+1) -> 1435.426 | O14: =Forecast!J$7*INDEX('Churn Curve'!$C$4:$C$28,5+1) -> 1315.6682 | P14: =Forecast!J$7*INDEX('Churn Curve'!$C$4:$C$28,6+1) -> 1214.6679 | Q14: =Forecast!J$7*INDEX('Churn Curve'!$C$4:$C$28,7+1) -> 1127.7575 | R14: =Forecast!J$7*INDEX('Churn Curve'!$C$4:$C$28,8+1) -> 1051.8374 | S14: =Forecast!J$7*INDEX('Churn Curve'!$C$4:$C$28,9+1) -> 984.73494 | T14: =Forecast!J$7*INDEX('Churn Curve'!$C$4:$C$28,10+1) -> 924.8634 | U14: =Forecast!J$7*INDEX('Churn Curve'!$C$4:$C$28,11+1) -> 871.02616 | V14: =Forecast!J$7*INDEX('Churn Curve'!$C$4:$C$28,12+1) -> 822.29737 | W14: =Forecast!J$7*INDEX('Churn Curve'!$C$4:$C$28,13+1) -> 777.94526 | X14: =Forecast!J$7*INDEX('Churn Curve'!$C$4:$C$28,14+1) -> 737.38114 | Y14: =Forecast!J$7*INDEX('Churn Curve'!$C$4:$C$28,15+1) -> 700.12425
A15: 2026-10 | B15: 0 | C15: 0 | D15: 0 | E15: 0 | F15: 0 | G15: 0 | H15: 0 | I15: 0 | J15: 0 | K15: =Forecast!K$7*INDEX('Churn Curve'!$C$4:$C$28,0+1) -> 2481.4872 | L15: =Forecast!K$7*INDEX('Churn Curve'!$C$4:$C$28,1+1) -> 2049.8507 | M15: =Forecast!K$7*INDEX('Churn Curve'!$C$4:$C$28,2+1) -> 1790.0103 | N15: =Forecast!K$7*INDEX('Churn Curve'!$C$4:$C$28,3+1) -> 1601.4486 | O15: =Forecast!K$7*INDEX('Churn Curve'!$C$4:$C$28,4+1) -> 1453.512 | P15: =Forecast!K$7*INDEX('Churn Curve'!$C$4:$C$28,5+1) -> 1332.2453 | Q15: =Forecast!K$7*INDEX('Churn Curve'!$C$4:$C$28,6+1) -> 1229.9725 | R15: =Forecast!K$7*INDEX('Churn Curve'!$C$4:$C$28,7+1) -> 1141.9669 | S15: =Forecast!K$7*INDEX('Churn Curve'!$C$4:$C$28,8+1) -> 1065.0903 | T15: =Forecast!K$7*INDEX('Churn Curve'!$C$4:$C$28,9+1) -> 997.14237 | U15: =Forecast!K$7*INDEX('Churn Curve'!$C$4:$C$28,10+1) -> 936.51646 | V15: =Forecast!K$7*INDEX('Churn Curve'!$C$4:$C$28,11+1) -> 882.00089 | W15: =Forecast!K$7*INDEX('Churn Curve'!$C$4:$C$28,12+1) -> 832.65812 | X15: =Forecast!K$7*INDEX('Churn Curve'!$C$4:$C$28,13+1) -> 787.74719 | Y15: =Forecast!K$7*INDEX('Churn Curve'!$C$4:$C$28,14+1) -> 746.67198
A16: 2026-11 | B16: 0 | C16: 0 | D16: 0 | E16: 0 | F16: 0 | G16: 0 | H16: 0 | I16: 0 | J16: 0 | K16: 0 | L16: =Forecast!L$7*INDEX('Churn Curve'!$C$4:$C$28,0+1) -> 2512.7533 | M16: =Forecast!L$7*INDEX('Churn Curve'!$C$4:$C$28,1+1) -> 2075.6783 | N16: =Forecast!L$7*INDEX('Churn Curve'!$C$4:$C$28,2+1) -> 1812.564 | O16: =Forecast!L$7*INDEX('Churn Curve'!$C$4:$C$28,3+1) -> 1621.6265 | P16: =Forecast!L$7*INDEX('Churn Curve'!$C$4:$C$28,4+1) -> 1471.8259 | Q16: =Forecast!L$7*INDEX('Churn Curve'!$C$4:$C$28,5+1) -> 1349.0313 | R16: =Forecast!L$7*INDEX('Churn Curve'!$C$4:$C$28,6+1) -> 1245.4699 | S16: =Forecast!L$7*INDEX('Churn Curve'!$C$4:$C$28,7+1) -> 1156.3555 | T16: =Forecast!L$7*INDEX('Churn Curve'!$C$4:$C$28,8+1) -> 1078.5102 | U16: =Forecast!L$7*INDEX('Churn Curve'!$C$4:$C$28,9+1) -> 1009.7061 | V16: =Forecast!L$7*INDEX('Churn Curve'!$C$4:$C$28,10+1) -> 948.31635 | W16: =Forecast!L$7*INDEX('Churn Curve'!$C$4:$C$28,11+1) -> 893.1139 | X16: =Forecast!L$7*INDEX('Churn Curve'!$C$4:$C$28,12+1) -> 843.14942 | Y16: =Forecast!L$7*INDEX('Churn Curve'!$C$4:$C$28,13+1) -> 797.67262
A17: 2026-12 | B17: 0 | C17: 0 | D17: 0 | E17: 0 | F17: 0 | G17: 0 | H17: 0 | I17: 0 | J17: 0 | K17: 0 | L17: 0 | M17: =Forecast!M$7*INDEX('Churn Curve'!$C$4:$C$28,0+1) -> 2544.4134 | N17: =Forecast!M$7*INDEX('Churn Curve'!$C$4:$C$28,1+1) -> 2101.8314 | O17: =Forecast!M$7*INDEX('Churn Curve'!$C$4:$C$28,2+1) -> 1835.4019 | P17: =Forecast!M$7*INDEX('Churn Curve'!$C$4:$C$28,3+1) -> 1642.0586 | Q17: =Forecast!M$7*INDEX('Churn Curve'!$C$4:$C$28,4+1) -> 1490.3706 | R17: =Forecast!M$7*INDEX('Churn Curve'!$C$4:$C$28,5+1) -> 1366.0288 | S17: =Forecast!M$7*INDEX('Churn Curve'!$C$4:$C$28,6+1) -> 1261.1625 | T17: =Forecast!M$7*INDEX('Churn Curve'!$C$4:$C$28,7+1) -> 1170.9253 | U17: =Forecast!M$7*INDEX('Churn Curve'!$C$4:$C$28,8+1) -> 1092.0991 | V17: =Forecast!M$7*INDEX('Churn Curve'!$C$4:$C$28,9+1) -> 1022.4282 | W17: =Forecast!M$7*INDEX('Churn Curve'!$C$4:$C$28,10+1) -> 960.26492 | X17: =Forecast!M$7*INDEX('Churn Curve'!$C$4:$C$28,11+1) -> 904.36692 | Y17: =Forecast!M$7*INDEX('Churn Curve'!$C$4:$C$28,12+1) -> 853.77291
A18: 2027-01 | B18: 0 | C18: 0 | D18: 0 | E18: 0 | F18: 0 | G18: 0 | H18: 0 | I18: 0 | J18: 0 | K18: 0 | L18: 0 | M18: 0 | N18: =Forecast!N$7*INDEX('Churn Curve'!$C$4:$C$28,0+1) -> 2819.4803 | O18: =Forecast!N$7*INDEX('Churn Curve'!$C$4:$C$28,1+1) -> 2329.0524 | P18: =Forecast!N$7*INDEX('Churn Curve'!$C$4:$C$28,2+1) -> 2033.8202 | Q18: =Forecast!N$7*INDEX('Churn Curve'!$C$4:$C$28,3+1) -> 1819.5753 | R18: =Forecast!N$7*INDEX('Churn Curve'!$C$4:$C$28,4+1) -> 1651.4889 | S18: =Forecast!N$7*INDEX('Churn Curve'!$C$4:$C$28,5+1) -> 1513.705 | T18: =Forecast!N$7*INDEX('Churn Curve'!$C$4:$C$28,6+1) -> 1397.502 | U18: =Forecast!N$7*INDEX('Churn Curve'!$C$4:$C$28,7+1) -> 1297.5095 | V18: =Forecast!N$7*INDEX('Churn Curve'!$C$4:$C$28,8+1) -> 1210.1618 | W18: =Forecast!N$7*INDEX('Churn Curve'!$C$4:$C$28,9+1) -> 1132.959 | X18: =Forecast!N$7*INDEX('Churn Curve'!$C$4:$C$28,10+1) -> 1064.0755 | Y18: =Forecast!N$7*INDEX('Churn Curve'!$C$4:$C$28,11+1) -> 1002.1346
A19: 2027-02 | B19: 0 | C19: 0 | D19: 0 | E19: 0 | F19: 0 | G19: 0 | H19: 0 | I19: 0 | J19: 0 | K19: 0 | L19: 0 | M19: 0 | N19: 0 | O19: =Forecast!O$7*INDEX('Churn Curve'!$C$4:$C$28,0+1) -> 2608.9354 | P19: =Forecast!O$7*INDEX('Churn Curve'!$C$4:$C$28,1+1) -> 2155.1302 | Q19: =Forecast!O$7*INDEX('Churn Curve'!$C$4:$C$28,2+1) -> 1881.9446 | R19: =Forecast!O$7*INDEX('Churn Curve'!$C$4:$C$28,3+1) -> 1683.6984 | S19: =Forecast!O$7*INDEX('Churn Curve'!$C$4:$C$28,4+1) -> 1528.1638 | T19: =Forecast!O$7*INDEX('Churn Curve'!$C$4:$C$28,5+1) -> 1400.669 | U19: =Forecast!O$7*INDEX('Churn Curve'!$C$4:$C$28,6+1) -> 1293.1434 | V19: =Forecast!O$7*INDEX('Churn Curve'!$C$4:$C$28,7+1) -> 1200.6179 | W19: =Forecast!O$7*INDEX('Churn Curve'!$C$4:$C$28,8+1) -> 1119.7929 | X19: =Forecast!O$7*INDEX('Churn Curve'!$C$4:$C$28,9+1) -> 1048.3552 | Y19: =Forecast!O$7*INDEX('Churn Curve'!$C$4:$C$28,10+1) -> 984.61559
A20: 2027-03 | B20: 0 | C20: 0 | D20: 0 | E20: 0 | F20: 0 | G20: 0 | H20: 0 | I20: 0 | J20: 0 | K20: 0 | L20: 0 | M20: 0 | N20: 0 | O20: 0 | P20: =Forecast!P$7*INDEX('Churn Curve'!$C$4:$C$28,0+1) -> 2641.8074 | Q20: =Forecast!P$7*INDEX('Churn Curve'!$C$4:$C$28,1+1) -> 2182.2844 | R20: =Forecast!P$7*INDEX('Churn Curve'!$C$4:$C$28,2+1) -> 1905.6566 | S20: =Forecast!P$7*INDEX('Churn Curve'!$C$4:$C$28,3+1) -> 1704.9126 | T20: =Forecast!P$7*INDEX('Churn Curve'!$C$4:$C$28,4+1) -> 1547.4183 | U20: =Forecast!P$7*INDEX('Churn Curve'!$C$4:$C$28,5+1) -> 1418.3171 | V20: =Forecast!P$7*INDEX('Churn Curve'!$C$4:$C$28,6+1) -> 1309.4367 | W20: =Forecast!P$7*INDEX('Churn Curve'!$C$4:$C$28,7+1) -> 1215.7454 | X20: =Forecast!P$7*INDEX('Churn Curve'!$C$4:$C$28,8+1) -> 1133.902 | Y20: =Forecast!P$7*INDEX('Churn Curve'!$C$4:$C$28,9+1) -> 1061.5643
A21: 2027-04 | B21: 0 | C21: 0 | D21: 0 | E21: 0 | F21: 0 | G21: 0 | H21: 0 | I21: 0 | J21: 0 | K21: 0 | L21: 0 | M21: 0 | N21: 0 | O21: 0 | P21: 0 | Q21: =Forecast!Q$7*INDEX('Churn Curve'!$C$4:$C$28,0+1) -> 2675.0936 | R21: =Forecast!Q$7*INDEX('Churn Curve'!$C$4:$C$28,1+1) -> 2209.7807 | S21: =Forecast!Q$7*INDEX('Churn Curve'!$C$4:$C$28,2+1) -> 1929.6675 | T21: =Forecast!Q$7*INDEX('Churn Curve'!$C$4:$C$28,3+1) -> 1726.3942 | U21: =Forecast!Q$7*INDEX('Churn Curve'!$C$4:$C$28,4+1) -> 1566.9155 | V21: =Forecast!Q$7*INDEX('Churn Curve'!$C$4:$C$28,5+1) -> 1436.1875 | W21: =Forecast!Q$7*INDEX('Churn Curve'!$C$4:$C$28,6+1) -> 1325.9353 | X21: =Forecast!Q$7*INDEX('Churn Curve'!$C$4:$C$28,7+1) -> 1231.0636 | Y21: =Forecast!Q$7*INDEX('Churn Curve'!$C$4:$C$28,8+1) -> 1148.1889
A22: 2027-05 | B22: 0 | C22: 0 | D22: 0 | E22: 0 | F22: 0 | G22: 0 | H22: 0 | I22: 0 | J22: 0 | K22: 0 | L22: 0 | M22: 0 | N22: 0 | O22: 0 | P22: 0 | Q22: 0 | R22: =Forecast!R$7*INDEX('Churn Curve'!$C$4:$C$28,0+1) -> 2708.7991 | S22: =Forecast!R$7*INDEX('Churn Curve'!$C$4:$C$28,1+1) -> 2237.6234 | T22: =Forecast!R$7*INDEX('Churn Curve'!$C$4:$C$28,2+1) -> 1953.9808 | U22: =Forecast!R$7*INDEX('Churn Curve'!$C$4:$C$28,3+1) -> 1748.1463 | V22: =Forecast!R$7*INDEX('Churn Curve'!$C$4:$C$28,4+1) -> 1586.6582 | W22: =Forecast!R$7*INDEX('Churn Curve'!$C$4:$C$28,5+1) -> 1454.2832 | X22: =Forecast!R$7*INDEX('Churn Curve'!$C$4:$C$28,6+1) -> 1342.6418 | Y22: =Forecast!R$7*INDEX('Churn Curve'!$C$4:$C$28,7+1) -> 1246.5747
A23: 2027-06 | B23: 0 | C23: 0 | D23: 0 | E23: 0 | F23: 0 | G23: 0 | H23: 0 | I23: 0 | J23: 0 | K23: 0 | L23: 0 | M23: 0 | N23: 0 | O23: 0 | P23: 0 | Q23: 0 | R23: 0 | S23: =Forecast!S$7*INDEX('Churn Curve'!$C$4:$C$28,0+1) -> 2742.9294 | T23: =Forecast!S$7*INDEX('Churn Curve'!$C$4:$C$28,1+1) -> 2265.8169 | U23: =Forecast!S$7*INDEX('Churn Curve'!$C$4:$C$28,2+1) -> 1978.6005 | V23: =Forecast!S$7*INDEX('Churn Curve'!$C$4:$C$28,3+1) -> 1770.1726 | W23: =Forecast!S$7*INDEX('Churn Curve'!$C$4:$C$28,4+1) -> 1606.6498 | X23: =Forecast!S$7*INDEX('Churn Curve'!$C$4:$C$28,5+1) -> 1472.6068 | Y23: =Forecast!S$7*INDEX('Churn Curve'!$C$4:$C$28,6+1) -> 1359.5588
A24: 2027-07 | B24: 0 | C24: 0 | D24: 0 | E24: 0 | F24: 0 | G24: 0 | H24: 0 | I24: 0 | J24: 0 | K24: 0 | L24: 0 | M24: 0 | N24: 0 | O24: 0 | P24: 0 | Q24: 0 | R24: 0 | S24: 0 | T24: =Forecast!T$7*INDEX('Churn Curve'!$C$4:$C$28,0+1) -> 2777.4896 | U24: =Forecast!T$7*INDEX('Churn Curve'!$C$4:$C$28,1+1) -> 2294.3657 | V24: =Forecast!T$7*INDEX('Churn Curve'!$C$4:$C$28,2+1) -> 2003.5304 | W24: =Forecast!T$7*INDEX('Churn Curve'!$C$4:$C$28,3+1) -> 1792.4763 | X24: =Forecast!T$7*INDEX('Churn Curve'!$C$4:$C$28,4+1) -> 1626.8932 | Y24: =Forecast!T$7*INDEX('Churn Curve'!$C$4:$C$28,5+1) -> 1491.1613
A25: 2027-08 | B25: 0 | C25: 0 | D25: 0 | E25: 0 | F25: 0 | G25: 0 | H25: 0 | I25: 0 | J25: 0 | K25: 0 | L25: 0 | M25: 0 | N25: 0 | O25: 0 | P25: 0 | Q25: 0 | R25: 0 | S25: 0 | T25: 0 | U25: =Forecast!U$7*INDEX('Churn Curve'!$C$4:$C$28,0+1) -> 2812.4853 | V25: =Forecast!U$7*INDEX('Churn Curve'!$C$4:$C$28,1+1) -> 2323.2742 | W25: =Forecast!U$7*INDEX('Churn Curve'!$C$4:$C$28,2+1) -> 2028.7745 | X25: =Forecast!U$7*INDEX('Churn Curve'!$C$4:$C$28,3+1) -> 1815.0611 | Y25: =Forecast!U$7*INDEX('Churn Curve'!$C$4:$C$28,4+1) -> 1647.3916
A26: 2027-09 | B26: 0 | C26: 0 | D26: 0 | E26: 0 | F26: 0 | G26: 0 | H26: 0 | I26: 0 | J26: 0 | K26: 0 | L26: 0 | M26: 0 | N26: 0 | O26: 0 | P26: 0 | Q26: 0 | R26: 0 | S26: 0 | T26: 0 | U26: 0 | V26: =Forecast!V$7*INDEX('Churn Curve'!$C$4:$C$28,0+1) -> 2847.922 | W26: =Forecast!V$7*INDEX('Churn Curve'!$C$4:$C$28,1+1) -> 2352.5469 | X26: =Forecast!V$7*INDEX('Churn Curve'!$C$4:$C$28,2+1) -> 2054.3365 | Y26: =Forecast!V$7*INDEX('Churn Curve'!$C$4:$C$28,3+1) -> 1837.9305
A27: 2027-10 | B27: 0 | C27: 0 | D27: 0 | E27: 0 | F27: 0 | G27: 0 | H27: 0 | I27: 0 | J27: 0 | K27: 0 | L27: 0 | M27: 0 | N27: 0 | O27: 0 | P27: 0 | Q27: 0 | R27: 0 | S27: 0 | T27: 0 | U27: 0 | V27: 0 | W27: =Forecast!W$7*INDEX('Churn Curve'!$C$4:$C$28,0+1) -> 2883.8052 | X27: =Forecast!W$7*INDEX('Churn Curve'!$C$4:$C$28,1+1) -> 2382.1884 | Y27: =Forecast!W$7*INDEX('Churn Curve'!$C$4:$C$28,2+1) -> 2080.2207
A28: 2027-11 | B28: 0 | C28: 0 | D28: 0 | E28: 0 | F28: 0 | G28: 0 | H28: 0 | I28: 0 | J28: 0 | K28: 0 | L28: 0 | M28: 0 | N28: 0 | O28: 0 | P28: 0 | Q28: 0 | R28: 0 | S28: 0 | T28: 0 | U28: 0 | V28: 0 | W28: 0 | X28: =Forecast!X$7*INDEX('Churn Curve'!$C$4:$C$28,0+1) -> 2920.1404 | Y28: =Forecast!X$7*INDEX('Churn Curve'!$C$4:$C$28,1+1) -> 2412.2034
A29: 2027-12 | B29: 0 | C29: 0 | D29: 0 | E29: 0 | F29: 0 | G29: 0 | H29: 0 | I29: 0 | J29: 0 | K29: 0 | L29: 0 | M29: 0 | N29: 0 | O29: 0 | P29: 0 | Q29: 0 | R29: 0 | S29: 0 | T29: 0 | U29: 0 | V29: 0 | W29: 0 | X29: 0 | Y29: =Forecast!Y$7*INDEX('Churn Curve'!$C$4:$C$28,0+1) -> 2956.9335
A30: Total | B30: =SUM(B6:B29) -> 2629.7586 | C30: =SUM(C6:C29) -> 4417.2957 | D30: =SUM(D6:D29) -> 6024.6849 | E30: =SUM(E6:E29) -> 7496.2603 | F30: =SUM(F6:F29) -> 8861.3586 | G30: =SUM(G6:G29) -> 10140.06 | H30: =SUM(H6:H29) -> 11346.912 | I30: =SUM(I6:I29) -> 12492.93 | ... Y30: =SUM(Y6:Y29) -> 26723.737
A33: Annual plan: new payers x renewal rate at each anniversary
A34: Cohort start | B34: 2026-01 | C34: 2026-02 | D34: 2026-03 | E34: 2026-04 | F34: 2026-05 | G34: 2026-06 | H34: 2026-07 | I34: 2026-08 | J34: 2026-09 | K34: 2026-10 | L34: 2026-11 | M34: 2026-12 | N34: 2027-01 | O34: 2027-02 | P34: 2027-03 | Q34: 2027-04 | R34: 2027-05 | S34: 2027-06 | T34: 2027-07 | U34: 2027-08 | V34: 2027-09 | W34: 2027-10 | X34: 2027-11 | Y34: 2027-12
A35: 2026-01 | B35: =Forecast!B$8*Inputs!$B$12^INT((1-1)/12) -> 888.01577 | C35: =Forecast!B$8*Inputs!$B$12^INT((2-1)/12) -> 888.01577 | D35: =Forecast!B$8*Inputs!$B$12^INT((3-1)/12) -> 888.01577 | E35: =Forecast!B$8*Inputs!$B$12^INT((4-1)/12) -> 888.01577 | F35: =Forecast!B$8*Inputs!$B$12^INT((5-1)/12) -> 888.01577 | G35: =Forecast!B$8*Inputs!$B$12^INT((6-1)/12) -> 888.01577 | H35: =Forecast!B$8*Inputs!$B$12^INT((7-1)/12) -> 888.01577 | I35: =Forecast!B$8*Inputs!$B$12^INT((8-1)/12) -> 888.01577 | J35: =Forecast!B$8*Inputs!$B$12^INT((9-1)/12) -> 888.01577 | K35: =Forecast!B$8*Inputs!$B$12^INT((10-1)/12) -> 888.01577 | L35: =Forecast!B$8*Inputs!$B$12^INT((11-1)/12) -> 888.01577 | M35: =Forecast!B$8*Inputs!$B$12^INT((12-1)/12) -> 888.01577 | N35: =Forecast!B$8*Inputs!$B$12^INT((13-1)/12) -> 622.42271 | O35: =Forecast!B$8*Inputs!$B$12^INT((14-1)/12) -> 622.42271 | P35: =Forecast!B$8*Inputs!$B$12^INT((15-1)/12) -> 622.42271 | Q35: =Forecast!B$8*Inputs!$B$12^INT((16-1)/12) -> 622.42271 | R35: =Forecast!B$8*Inputs!$B$12^INT((17-1)/12) -> 622.42271 | S35: =Forecast!B$8*Inputs!$B$12^INT((18-1)/12) -> 622.42271 | T35: =Forecast!B$8*Inputs!$B$12^INT((19-1)/12) -> 622.42271 | U35: =Forecast!B$8*Inputs!$B$12^INT((20-1)/12) -> 622.42271 | V35: =Forecast!B$8*Inputs!$B$12^INT((21-1)/12) -> 622.42271 | W35: =Forecast!B$8*Inputs!$B$12^INT((22-1)/12) -> 622.42271 | X35: =Forecast!B$8*Inputs!$B$12^INT((23-1)/12) -> 622.42271 | Y35: =Forecast!B$8*Inputs!$B$12^INT((24-1)/12) -> 622.42271
A36: 2026-02 | B36: 0 | C36: =Forecast!C$8*Inputs!$B$12^INT((2-2)/12) -> 758.0786 | D36: =Forecast!C$8*Inputs!$B$12^INT((3-2)/12) -> 758.0786 | E36: =Forecast!C$8*Inputs!$B$12^INT((4-2)/12) -> 758.0786 | F36: =Forecast!C$8*Inputs!$B$12^INT((5-2)/12) -> 758.0786 | G36: =Forecast!C$8*Inputs!$B$12^INT((6-2)/12) -> 758.0786 | H36: =Forecast!C$8*Inputs!$B$12^INT((7-2)/12) -> 758.0786 | I36: =Forecast!C$8*Inputs!$B$12^INT((8-2)/12) -> 758.0786 | J36: =Forecast!C$8*Inputs!$B$12^INT((9-2)/12) -> 758.0786 | K36: =Forecast!C$8*Inputs!$B$12^INT((10-2)/12) -> 758.0786 | L36: =Forecast!C$8*Inputs!$B$12^INT((11-2)/12) -> 758.0786 | M36: =Forecast!C$8*Inputs!$B$12^INT((12-2)/12) -> 758.0786 | N36: =Forecast!C$8*Inputs!$B$12^INT((13-2)/12) -> 758.0786 | O36: =Forecast!C$8*Inputs!$B$12^INT((14-2)/12) -> 531.34793 | P36: =Forecast!C$8*Inputs!$B$12^INT((15-2)/12) -> 531.34793 | Q36: =Forecast!C$8*Inputs!$B$12^INT((16-2)/12) -> 531.34793 | R36: =Forecast!C$8*Inputs!$B$12^INT((17-2)/12) -> 531.34793 | S36: =Forecast!C$8*Inputs!$B$12^INT((18-2)/12) -> 531.34793 | T36: =Forecast!C$8*Inputs!$B$12^INT((19-2)/12) -> 531.34793 | U36: =Forecast!C$8*Inputs!$B$12^INT((20-2)/12) -> 531.34793 | V36: =Forecast!C$8*Inputs!$B$12^INT((21-2)/12) -> 531.34793 | W36: =Forecast!C$8*Inputs!$B$12^INT((22-2)/12) -> 531.34793 | X36: =Forecast!C$8*Inputs!$B$12^INT((23-2)/12) -> 531.34793 | Y36: =Forecast!C$8*Inputs!$B$12^INT((24-2)/12) -> 531.34793
A37: 2026-03 | B37: 0 | C37: 0 | D37: =Forecast!D$8*Inputs!$B$12^INT((3-3)/12) -> 767.63021 | E37: =Forecast!D$8*Inputs!$B$12^INT((4-3)/12) -> 767.63021 | F37: =Forecast!D$8*Inputs!$B$12^INT((5-3)/12) -> 767.63021 | G37: =Forecast!D$8*Inputs!$B$12^INT((6-3)/12) -> 767.63021 | H37: =Forecast!D$8*Inputs!$B$12^INT((7-3)/12) -> 767.63021 | I37: =Forecast!D$8*Inputs!$B$12^INT((8-3)/12) -> 767.63021 | J37: =Forecast!D$8*Inputs!$B$12^INT((9-3)/12) -> 767.63021 | K37: =Forecast!D$8*Inputs!$B$12^INT((10-3)/12) -> 767.63021 | L37: =Forecast!D$8*Inputs!$B$12^INT((11-3)/12) -> 767.63021 | M37: =Forecast!D$8*Inputs!$B$12^INT((12-3)/12) -> 767.63021 | N37: =Forecast!D$8*Inputs!$B$12^INT((13-3)/12) -> 767.63021 | O37: =Forecast!D$8*Inputs!$B$12^INT((14-3)/12) -> 767.63021 | P37: =Forecast!D$8*Inputs!$B$12^INT((15-3)/12) -> 538.04279 | Q37: =Forecast!D$8*Inputs!$B$12^INT((16-3)/12) -> 538.04279 | R37: =Forecast!D$8*Inputs!$B$12^INT((17-3)/12) -> 538.04279 | S37: =Forecast!D$8*Inputs!$B$12^INT((18-3)/12) -> 538.04279 | T37: =Forecast!D$8*Inputs!$B$12^INT((19-3)/12) -> 538.04279 | U37: =Forecast!D$8*Inputs!$B$12^INT((20-3)/12) -> 538.04279 | V37: =Forecast!D$8*Inputs!$B$12^INT((21-3)/12) -> 538.04279 | W37: =Forecast!D$8*Inputs!$B$12^INT((22-3)/12) -> 538.04279 | X37: =Forecast!D$8*Inputs!$B$12^INT((23-3)/12) -> 538.04279 | Y37: =Forecast!D$8*Inputs!$B$12^INT((24-3)/12) -> 538.04279
A38: 2026-04 | B38: 0 | C38: 0 | D38: 0 | E38: =Forecast!E$8*Inputs!$B$12^INT((4-4)/12) -> 777.30218 | F38: =Forecast!E$8*Inputs!$B$12^INT((5-4)/12) -> 777.30218 | G38: =Forecast!E$8*Inputs!$B$12^INT((6-4)/12) -> 777.30218 | H38: =Forecast!E$8*Inputs!$B$12^INT((7-4)/12) -> 777.30218 | I38: =Forecast!E$8*Inputs!$B$12^INT((8-4)/12) -> 777.30218 | J38: =Forecast!E$8*Inputs!$B$12^INT((9-4)/12) -> 777.30218 | K38: =Forecast!E$8*Inputs!$B$12^INT((10-4)/12) -> 777.30218 | L38: =Forecast!E$8*Inputs!$B$12^INT((11-4)/12) -> 777.30218 | M38: =Forecast!E$8*Inputs!$B$12^INT((12-4)/12) -> 777.30218 | N38: =Forecast!E$8*Inputs!$B$12^INT((13-4)/12) -> 777.30218 | O38: =Forecast!E$8*Inputs!$B$12^INT((14-4)/12) -> 777.30218 | P38: =Forecast!E$8*Inputs!$B$12^INT((15-4)/12) -> 777.30218 | Q38: =Forecast!E$8*Inputs!$B$12^INT((16-4)/12) -> 544.822 | R38: =Forecast!E$8*Inputs!$B$12^INT((17-4)/12) -> 544.822 | S38: =Forecast!E$8*Inputs!$B$12^INT((18-4)/12) -> 544.822 | T38: =Forecast!E$8*Inputs!$B$12^INT((19-4)/12) -> 544.822 | U38: =Forecast!E$8*Inputs!$B$12^INT((20-4)/12) -> 544.822 | V38: =Forecast!E$8*Inputs!$B$12^INT((21-4)/12) -> 544.822 | W38: =Forecast!E$8*Inputs!$B$12^INT((22-4)/12) -> 544.822 | X38: =Forecast!E$8*Inputs!$B$12^INT((23-4)/12) -> 544.822 | Y38: =Forecast!E$8*Inputs!$B$12^INT((24-4)/12) -> 544.822
A39: 2026-05 | B39: 0 | C39: 0 | D39: 0 | E39: 0 | F39: =Forecast!F$8*Inputs!$B$12^INT((5-5)/12) -> 787.096 | G39: =Forecast!F$8*Inputs!$B$12^INT((6-5)/12) -> 787.096 | H39: =Forecast!F$8*Inputs!$B$12^INT((7-5)/12) -> 787.096 | I39: =Forecast!F$8*Inputs!$B$12^INT((8-5)/12) -> 787.096 | J39: =Forecast!F$8*Inputs!$B$12^INT((9-5)/12) -> 787.096 | K39: =Forecast!F$8*Inputs!$B$12^INT((10-5)/12) -> 787.096 | L39: =Forecast!F$8*Inputs!$B$12^INT((11-5)/12) -> 787.096 | M39: =Forecast!F$8*Inputs!$B$12^INT((12-5)/12) -> 787.096 | N39: =Forecast!F$8*Inputs!$B$12^INT((13-5)/12) -> 787.096 | O39: =Forecast!F$8*Inputs!$B$12^INT((14-5)/12) -> 787.096 | P39: =Forecast!F$8*Inputs!$B$12^INT((15-5)/12) -> 787.096 | Q39: =Forecast!F$8*Inputs!$B$12^INT((16-5)/12) -> 787.096 | R39: =Forecast!F$8*Inputs!$B$12^INT((17-5)/12) -> 551.68664 | S39: =Forecast!F$8*Inputs!$B$12^INT((18-5)/12) -> 551.68664 | T39: =Forecast!F$8*Inputs!$B$12^INT((19-5)/12) -> 551.68664 | U39: =Forecast!F$8*Inputs!$B$12^INT((20-5)/12) -> 551.68664 | V39: =Forecast!F$8*Inputs!$B$12^INT((21-5)/12) -> 551.68664 | W39: =Forecast!F$8*Inputs!$B$12^INT((22-5)/12) -> 551.68664 | X39: =Forecast!F$8*Inputs!$B$12^INT((23-5)/12) -> 551.68664 | Y39: =Forecast!F$8*Inputs!$B$12^INT((24-5)/12) -> 551.68664
A40: 2026-06 | B40: 0 | C40: 0 | D40: 0 | E40: 0 | F40: 0 | G40: =Forecast!G$8*Inputs!$B$12^INT((6-6)/12) -> 797.01323 | H40: =Forecast!G$8*Inputs!$B$12^INT((7-6)/12) -> 797.01323 | I40: =Forecast!G$8*Inputs!$B$12^INT((8-6)/12) -> 797.01323 | J40: =Forecast!G$8*Inputs!$B$12^INT((9-6)/12) -> 797.01323 | K40: =Forecast!G$8*Inputs!$B$12^INT((10-6)/12) -> 797.01323 | L40: =Forecast!G$8*Inputs!$B$12^INT((11-6)/12) -> 797.01323 | M40: =Forecast!G$8*Inputs!$B$12^INT((12-6)/12) -> 797.01323 | N40: =Forecast!G$8*Inputs!$B$12^INT((13-6)/12) -> 797.01323 | O40: =Forecast!G$8*Inputs!$B$12^INT((14-6)/12) -> 797.01323 | P40: =Forecast!G$8*Inputs!$B$12^INT((15-6)/12) -> 797.01323 | Q40: =Forecast!G$8*Inputs!$B$12^INT((16-6)/12) -> 797.01323 | R40: =Forecast!G$8*Inputs!$B$12^INT((17-6)/12) -> 797.01323 | S40: =Forecast!G$8*Inputs!$B$12^INT((18-6)/12) -> 558.63776 | T40: =Forecast!G$8*Inputs!$B$12^INT((19-6)/12) -> 558.63776 | U40: =Forecast!G$8*Inputs!$B$12^INT((20-6)/12) -> 558.63776 | V40: =Forecast!G$8*Inputs!$B$12^INT((21-6)/12) -> 558.63776 | W40: =Forecast!G$8*Inputs!$B$12^INT((22-6)/12) -> 558.63776 | X40: =Forecast!G$8*Inputs!$B$12^INT((23-6)/12) -> 558.63776 | Y40: =Forecast!G$8*Inputs!$B$12^INT((24-6)/12) -> 558.63776
A41: 2026-07 | B41: 0 | C41: 0 | D41: 0 | E41: 0 | F41: 0 | G41: 0 | H41: =Forecast!H$8*Inputs!$B$12^INT((7-7)/12) -> 807.05541 | I41: =Forecast!H$8*Inputs!$B$12^INT((8-7)/12) -> 807.05541 | J41: =Forecast!H$8*Inputs!$B$12^INT((9-7)/12) -> 807.05541 | K41: =Forecast!H$8*Inputs!$B$12^INT((10-7)/12) -> 807.05541 | L41: =Forecast!H$8*Inputs!$B$12^INT((11-7)/12) -> 807.05541 | M41: =Forecast!H$8*Inputs!$B$12^INT((12-7)/12) -> 807.05541 | N41: =Forecast!H$8*Inputs!$B$12^INT((13-7)/12) -> 807.05541 | O41: =Forecast!H$8*Inputs!$B$12^INT((14-7)/12) -> 807.05541 | P41: =Forecast!H$8*Inputs!$B$12^INT((15-7)/12) -> 807.05541 | Q41: =Forecast!H$8*Inputs!$B$12^INT((16-7)/12) -> 807.05541 | R41: =Forecast!H$8*Inputs!$B$12^INT((17-7)/12) -> 807.05541 | S41: =Forecast!H$8*Inputs!$B$12^INT((18-7)/12) -> 807.05541 | T41: =Forecast!H$8*Inputs!$B$12^INT((19-7)/12) -> 565.67647 | U41: =Forecast!H$8*Inputs!$B$12^INT((20-7)/12) -> 565.67647 | V41: =Forecast!H$8*Inputs!$B$12^INT((21-7)/12) -> 565.67647 | W41: =Forecast!H$8*Inputs!$B$12^INT((22-7)/12) -> 565.67647 | X41: =Forecast!H$8*Inputs!$B$12^INT((23-7)/12) -> 565.67647 | Y41: =Forecast!H$8*Inputs!$B$12^INT((24-7)/12) -> 565.67647
A42: 2026-08 | B42: 0 | C42: 0 | D42: 0 | E42: 0 | F42: 0 | G42: 0 | H42: 0 | I42: =Forecast!I$8*Inputs!$B$12^INT((8-8)/12) -> 817.22412 | J42: =Forecast!I$8*Inputs!$B$12^INT((9-8)/12) -> 817.22412 | K42: =Forecast!I$8*Inputs!$B$12^INT((10-8)/12) -> 817.22412 | L42: =Forecast!I$8*Inputs!$B$12^INT((11-8)/12) -> 817.22412 | M42: =Forecast!I$8*Inputs!$B$12^INT((12-8)/12) -> 817.22412 | N42: =Forecast!I$8*Inputs!$B$12^INT((13-8)/12) -> 817.22412 | O42: =Forecast!I$8*Inputs!$B$12^INT((14-8)/12) -> 817.22412 | P42: =Forecast!I$8*Inputs!$B$12^INT((15-8)/12) -> 817.22412 | Q42: =Forecast!I$8*Inputs!$B$12^INT((16-8)/12) -> 817.22412 | R42: =Forecast!I$8*Inputs!$B$12^INT((17-8)/12) -> 817.22412 | S42: =Forecast!I$8*Inputs!$B$12^INT((18-8)/12) -> 817.22412 | T42: =Forecast!I$8*Inputs!$B$12^INT((19-8)/12) -> 817.22412 | U42: =Forecast!I$8*Inputs!$B$12^INT((20-8)/12) -> 572.80386 | V42: =Forecast!I$8*Inputs!$B$12^INT((21-8)/12) -> 572.80386 | W42: =Forecast!I$8*Inputs!$B$12^INT((22-8)/12) -> 572.80386 | X42: =Forecast!I$8*Inputs!$B$12^INT((23-8)/12) -> 572.80386 | Y42: =Forecast!I$8*Inputs!$B$12^INT((24-8)/12) -> 572.80386
A43: 2026-09 | B43: 0 | C43: 0 | D43: 0 | E43: 0 | F43: 0 | G43: 0 | H43: 0 | I43: 0 | J43: =Forecast!J$8*Inputs!$B$12^INT((9-9)/12) -> 827.52096 | K43: =Forecast!J$8*Inputs!$B$12^INT((10-9)/12) -> 827.52096 | L43: =Forecast!J$8*Inputs!$B$12^INT((11-9)/12) -> 827.52096 | M43: =Forecast!J$8*Inputs!$B$12^INT((12-9)/12) -> 827.52096 | N43: =Forecast!J$8*Inputs!$B$12^INT((13-9)/12) -> 827.52096 | O43: =Forecast!J$8*Inputs!$B$12^INT((14-9)/12) -> 827.52096 | P43: =Forecast!J$8*Inputs!$B$12^INT((15-9)/12) -> 827.52096 | Q43: =Forecast!J$8*Inputs!$B$12^INT((16-9)/12) -> 827.52096 | R43: =Forecast!J$8*Inputs!$B$12^INT((17-9)/12) -> 827.52096 | S43: =Forecast!J$8*Inputs!$B$12^INT((18-9)/12) -> 827.52096 | T43: =Forecast!J$8*Inputs!$B$12^INT((19-9)/12) -> 827.52096 | U43: =Forecast!J$8*Inputs!$B$12^INT((20-9)/12) -> 827.52096 | V43: =Forecast!J$8*Inputs!$B$12^INT((21-9)/12) -> 580.02105 | W43: =Forecast!J$8*Inputs!$B$12^INT((22-9)/12) -> 580.02105 | X43: =Forecast!J$8*Inputs!$B$12^INT((23-9)/12) -> 580.02105 | Y43: =Forecast!J$8*Inputs!$B$12^INT((24-9)/12) -> 580.02105
A44: 2026-10 | B44: 0 | C44: 0 | D44: 0 | E44: 0 | F44: 0 | G44: 0 | H44: 0 | I44: 0 | J44: 0 | K44: =Forecast!K$8*Inputs!$B$12^INT((10-10)/12) -> 837.94753 | L44: =Forecast!K$8*Inputs!$B$12^INT((11-10)/12) -> 837.94753 | M44: =Forecast!K$8*Inputs!$B$12^INT((12-10)/12) -> 837.94753 | N44: =Forecast!K$8*Inputs!$B$12^INT((13-10)/12) -> 837.94753 | O44: =Forecast!K$8*Inputs!$B$12^INT((14-10)/12) -> 837.94753 | P44: =Forecast!K$8*Inputs!$B$12^INT((15-10)/12) -> 837.94753 | Q44: =Forecast!K$8*Inputs!$B$12^INT((16-10)/12) -> 837.94753 | R44: =Forecast!K$8*Inputs!$B$12^INT((17-10)/12) -> 837.94753 | S44: =Forecast!K$8*Inputs!$B$12^INT((18-10)/12) -> 837.94753 | T44: =Forecast!K$8*Inputs!$B$12^INT((19-10)/12) -> 837.94753 | U44: =Forecast!K$8*Inputs!$B$12^INT((20-10)/12) -> 837.94753 | V44: =Forecast!K$8*Inputs!$B$12^INT((21-10)/12) -> 837.94753 | W44: =Forecast!K$8*Inputs!$B$12^INT((22-10)/12) -> 587.32918 | X44: =Forecast!K$8*Inputs!$B$12^INT((23-10)/12) -> 587.32918 | Y44: =Forecast!K$8*Inputs!$B$12^INT((24-10)/12) -> 587.32918
...
